{
    "registryname": "charging_station",
    "localizedname": "Industrial Charging Station",
    "requires-blueprint": true,
    "parts": [
        {
            "x": -1,
            "y": 0,
            "z": 0,
            "elements": [
                "chisel:technicalnew@2"
            ]
        },
        {
            "x": -1,
            "y": 0,
            "z": 1,
            "elements": [
                "modularmachinery:blockinputbus@2"
            ]
        },
        {
            "x": 0,
            "y": 0,
            "z": 1,
            "elements": [
                "immersiveengineering:metal_device1@5"
            ]
        },
        {
            "x": 1,
            "y": 0,
            "z": 0,
            "elements": [
                "chisel:technicalnew@2"
            ]
        },
        {
            "x": -1,
            "y": 0,
            "z": 2,
            "elements": [
                "chisel:technicalnew@2"
            ]
        },
        {
            "x": 1,
            "y": 0,
            "z": 1,
            "elements": [
                "immersiveengineering:wooden_device0@3"
            ]
        },
        {
            "x": 0,
            "y": 0,
            "z": 2,
            "elements": [
                "industrialrenewal:battery_bank@2"
            ]
        },
        {
            "x": 2,
            "y": 0,
            "z": 0,
            "elements": [
                "chisel:technicalnew@2"
            ]
        },
        {
            "x": -1,
            "y": 0,
            "z": 3,
            "elements": [
                "chisel:technicalnew@2"
            ]
        },
        {
            "x": 2,
            "y": 0,
            "z": 1,
            "elements": [
                "modularmachinery:blockoutputbus@2"
            ]
        },
        {
            "x": 0,
            "y": 0,
            "z": 3,
            "elements": [
                "modularmachinery:blockenergyinputhatch@2"
            ]
        },
        {
            "x": 1,
            "y": 0,
            "z": 2,
            "elements": [
                "immersiveengineering:metal_decoration0@5"
            ]
        },
        {
            "x": 2,
            "y": 0,
            "z": 2,
            "elements": [
                "chisel:technicalnew@2"
            ]
        },
        {
            "x": 1,
            "y": 0,
            "z": 3,
            "elements": [
                "chisel:technicalnew@2"
            ]
        },
        {
            "x": 2,
            "y": 0,
            "z": 3,
            "elements": [
                "chisel:technicalnew@2"
            ]
        },
        {
            "x": 2,
            "y": -1,
            "z": 0,
            "elements": [
                "chisel:technicalnew@2"
            ]
        },
        {
            "x": 1,
            "y": -1,
            "z": 0,
            "elements": [
                "chisel:technicalnew@2"
            ]
        },
        {
            "x": 0,
            "y": -1,
            "z": 0,
            "elements": [
                "chisel:technicalnew@2"
            ]
        },
        {
            "x": -1,
            "y": 1,
            "z": 0,
            "elements": [
                "chisel:technicalnew@2"
            ]
        },
        {
            "x": -1,
            "y": -1,
            "z": 0,
            "elements": [
                "chisel:technicalnew@2"
            ]
        },
        {
            "x": 0,
            "y": 1,
            "z": 0,
            "elements": [
                "chisel:technicalnew@2"
            ]
        },
        {
            "x": -1,
            "y": 1,
            "z": 1,
            "elements": [
                "chisel:technicalnew@2"
            ]
        },
        {
            "x": 0,
            "y": 1,
            "z": 1,
            "elements": [
                "chisel:technicalnew@2"
            ]
        },
        {
            "x": 1,
            "y": 1,
            "z": 0,
            "elements": [
                "chisel:technicalnew@2"
            ]
        },
        {
            "x": -1,
            "y": 1,
            "z": 2,
            "elements": [
                "chisel:technicalnew@2"
            ]
        },
        {
            "x": 0,
            "y": 1,
            "z": 2,
            "elements": [
                "chisel:technicalnew@2"
            ]
        },
        {
            "x": 1,
            "y": 1,
            "z": 1,
            "elements": [
                "chisel:technicalnew@2"
            ]
        },
        {
            "x": -1,
            "y": -1,
            "z": 1,
            "elements": [
                "chisel:technicalnew@2"
            ]
        },
        {
            "x": 2,
            "y": 1,
            "z": 0,
            "elements": [
                "chisel:technicalnew@2"
            ]
        },
        {
            "x": -1,
            "y": 1,
            "z": 3,
            "elements": [
                "chisel:technicalnew@2"
            ]
        },
        {
            "x": 0,
            "y": 1,
            "z": 3,
            "elements": [
                "chisel:technicalnew@2"
            ]
        },
        {
            "x": 1,
            "y": 1,
            "z": 2,
            "elements": [
                "chisel:technicalnew@2"
            ]
        },
        {
            "x": 0,
            "y": -1,
            "z": 1,
            "elements": [
                "chisel:technicalnew@2"
            ]
        },
        {
            "x": 2,
            "y": 1,
            "z": 1,
            "elements": [
                "chisel:technicalnew@2"
            ]
        },
        {
            "x": -1,
            "y": -1,
            "z": 2,
            "elements": [
                "chisel:technicalnew@2"
            ]
        },
        {
            "x": 1,
            "y": 1,
            "z": 3,
            "elements": [
                "chisel:technicalnew@2"
            ]
        },
        {
            "x": 2,
            "y": 1,
            "z": 2,
            "elements": [
                "chisel:technicalnew@2"
            ]
        },
        {
            "x": 0,
            "y": -1,
            "z": 2,
            "elements": [
                "chisel:technicalnew@2"
            ]
        },
        {
            "x": 1,
            "y": -1,
            "z": 1,
            "elements": [
                "chisel:technicalnew@2"
            ]
        },
        {
            "x": -1,
            "y": -1,
            "z": 3,
            "elements": [
                "chisel:technicalnew@2"
            ]
        },
        {
            "x": 2,
            "y": 1,
            "z": 3,
            "elements": [
                "chisel:technicalnew@2"
            ]
        },
        {
            "x": 1,
            "y": -1,
            "z": 2,
            "elements": [
                "chisel:technicalnew@2"
            ]
        },
        {
            "x": 0,
            "y": -1,
            "z": 3,
            "elements": [
                "chisel:technicalnew@2"
            ]
        },
        {
            "x": 2,
            "y": -1,
            "z": 1,
            "elements": [
                "chisel:technicalnew@2"
            ]
        },
        {
            "x": 1,
            "y": -1,
            "z": 3,
            "elements": [
                "chisel:technicalnew@2"
            ]
        },
        {
            "x": 2,
            "y": -1,
            "z": 2,
            "elements": [
                "chisel:technicalnew@2"
            ]
        },
        {
            "x": 2,
            "y": -1,
            "z": 3,
            "elements": [
                "chisel:technicalnew@2"
            ]
        }
    ]}